Workbook
Name DimenRpta: [1]RESPUESTAS!$C$317:$AU$317
Name DimenRpta: [1]RESPUESTAS!$C$317:$AU$317
Name DimenRpta: [2]RESPUESTAS!$C$317:$AU$317
Name DimenRpta: RESPUESTAS!$D$147:$AO$147
Name Dimensiones: [1]RESPUESTAS!$C$310:$AU$310
Name Dimensiones: [1]RESPUESTAS!$C$310:$AU$310
Name Dimensiones: [2]RESPUESTAS!$C$310:$AU$310
Name Dimensiones: RESPUESTAS!$D$140:$AO$140

Sheet ESTRUCTURA
A1: ENCUESTA DE CLIMA LABORAL
A3: A. Marcar la respuesta según corresponda en las siguientes opciones:
A4: VARIABLES | B4: Nº | C4: ITEMS | D4: NUNCA | E4: CASI NUNCA | F4: A VECES | G4: CASI SIEMPRE | H4: SIEMPRE
A5: GENERALIDADES | B5: 1 | C5: Al finalizar mi jornada diaria, me siento satisfecho con el trabajo que realizo. | I5: =IF(D5="X","N",IF(E5="X","CN",IF(F5="X","AV",IF(G5="X","CS",IF(H5="X","S","")))))
B6: 2 | C6: DACHASAC facilita mi trabajo al ofrecer normas claras y procedimientos simples que son fáciles de seguir, lo que me permite realizar mis tareas con mayor rapidez y precisión.
B7: 3 | C7: Conozco las tareas o funciones específicas que debo realizar en DACHASAC. | I7: =IF(D7="X","N",IF(E7="X","CN",IF(F7="X","AV",IF(G7="X","CS",IF(H7="X","S","")))))
A8: COLABORACIÓN | B8: 4 | C8: En mi equipo de trabajo, puedo expresar mi punto de vista, aun cuando contradiga al de los demás miembros
B9: 5 | C9: Cuento con la colaboración de mis compañeros de área y de otras áreas cuando lo necesito
B10: 6 | C10: Tienes una relación sólida y una competencia sana dentro de tu equipo.
A11: VALORACIÓN - MOTIVACION | B11: 7 | C11: El trabajo que realizo es valorado por mi jefe inmediato y recibo retroalimentación y/o capacitación constante para mejorar mi desempeño. | I11: =IF(D11="X","N",IF(E11="X","CN",IF(F11="X","AV",IF(G11="X","CS",IF(H11="X","S","")))))
B12: 8 | C12: Mi jefe inmediato se preocupa por crear un ambiente laboral agradable, lo que me motiva a mejorar día a día.
B13: 9 | C13: Me gusta lo que hago, me siento motivado a mejorar y mi trabajo me permite desarrollar al máximo mis capacidades. | I13: =IF(D13="X","N",IF(E13="X","CN",IF(F13="X","AV",IF(G13="X","CS",IF(H13="X","S","")))))
A14: COMUNICACIÓN | B14: 10 | C14: Mi jefe inmediato me mantiene informado sobre cambios importantes del área y me brinda retroalimentación sobre mi desempeño | I14: =IF(D14="X","N",IF(E14="X","CN",IF(F14="X","AV",IF(G14="X","CS",IF(H14="X","S","")))))
B15: 11 | C15: Mi jefe inmediato escucha mis opiniones y me hace partícipe de las decisiones
B16: 12 | C16: En DACHASAC existen suficientes canales de comunicación. | I16: =IF(D16="X","N",IF(E16="X","CN",IF(F16="X","AV",IF(G16="X","CS",IF(H16="X","S","")))))
B17: 13 | C17: Las reuniones de coordinación con los miembros de otras áreas son frecuentes.
A18: FORMACIÓN | B18: 14 | C18: Las inducciones realizadas al momento de mi ingreso me ayudan a realizar las labores propias de mi puesto de trabajo | I18: =IF(D18="X","N",IF(E18="X","CN",IF(F18="X","AV",IF(G18="X","CS",IF(H18="X","S","")))))
B19: 15 | C19: DACHASAC me ofrece oportunidades para crecer profesionalmente | I19: =IF(D19="X","N",IF(E19="X","CN",IF(F19="X","AV",IF(G19="X","CS",IF(H19="X","S","")))))
B20: 16 | C20: DACHASAC me ofrece capacitaciones y/o entrenamientos para desarrollarme profesionalmente | I20: =IF(D20="X","N",IF(E20="X","CN",IF(F20="X","AV",IF(G20="X","CS",IF(H20="X","S","")))))
A21: LIDERAZGO | B21: 17 | C21: Mi jefe inmediato está disponible cuando lo necesito y brinda apoyo para superar los obstáculos que se presentan. | I21: =IF(D21="X","N",IF(E21="X","CN",IF(F21="X","AV",IF(G21="X","CS",IF(H21="X","S","")))))
B22: 18 | C22: Mi jefe inmediato es claro y específico al definir los objetivos de trabajo y maneja adecuadamente los conflictos.
B23: 19 | C23: Nuestros gerentes contribuyen a crear condiciones adecuadas para el progreso de DACHASAC | I23: =IF(D23="X","N",IF(E23="X","CN",IF(F23="X","AV",IF(G23="X","CS",IF(H23="X","S","")))))
A24: SEGURIDAD | B24: 20 | C24: Trabajo en un ambiente seguro y me siento satisfecho.
B25: 21 | C25: Dispongo de los materiales, equipos de protección personal y recursos necesarios para realizar mi trabajo de forma segura | I25: =IF(D25="X","N",IF(E25="X","CN",IF(F25="X","AV",IF(G25="X","CS",IF(H25="X","S","")))))
B26: 22 | C26: DACHASAC me proporciona de los equipos, herramientas y materiales a tiempo. | I26: =IF(D26="X","N",IF(E26="X","CN",IF(F26="X","AV",IF(G26="X","CS",IF(H26="X","S","")))))
A27: REMUNERACIÓN | B27: 23 | C27: Recibo mi remuneración a tiempo | I27: =IF(D27="X","N",IF(E27="X","CN",IF(F27="X","AV",IF(G27="X","CS",IF(H27="X","S","")))))
B28: 24 | C28: Existe equidad en las remuneraciones
B29: 25 | C29: Mi remuneración es adecuada en relación con el trabajo que realizo
B30: 26 | C30: Mi salario y beneficios son razonables y cubren mis necesidades básicas
A31: INNOVACION | B31: 27 | C31: Tengo la libertad de ser creativo e innovador en las soluciones de los problemas laborales que se presenten | I31: =IF(D31="X","N",IF(E31="X","CN",IF(F31="X","AV",IF(G31="X","CS",IF(H31="X","S","")))))
B32: 28 | C32: Considero que DACHASAC es flexible y se adapta bien a los cambios, por lo que la innovación es una de sus características | I32: =IF(D32="X","N",IF(E32="X","CN",IF(F32="X","AV",IF(G32="X","CS",IF(H32="X","S","")))))
B33: 29 | C33: Mis compañeros de trabajo toman iniciativas para la solución de problemas. | I33: =IF(D33="X","N",IF(E33="X","CN",IF(F33="X","AV",IF(G33="X","CS",IF(H33="X","S","")))))
B34: 30 | C34: Es fácil para mis compañeros de trabajo y para mí que nuestras nuevas ideas sean consideradas. | I34: =IF(D34="X","N",IF(E34="X","CN",IF(F34="X","AV",IF(G34="X","CS",IF(H34="X","S","")))))
A35: RECOMPENSA | B35: 31 | C35: Considero que los beneficios que me ofrecen en DACHASAC son los más justos y adecuados | I35: =IF(D35="X","N",IF(E35="X","CN",IF(F35="X","AV",IF(G35="X","CS",IF(H35="X","S","")))))
B36: 32 | C36: Existen incentivos laborales para que yo trate de hacer mejor mi trabajo | I36: =IF(D36="X","N",IF(E36="X","CN",IF(F36="X","AV",IF(G36="X","CS",IF(H36="X","S","")))))
B37: 33 | C37: Considero que cada trabajador es considerado factor clave para el éxito de DACHASAC. | I37: =IF(D37="X","N",IF(E37="X","CN",IF(F37="X","AV",IF(G37="X","CS",IF(H37="X","S","")))))
B38: 34 | C38: Las recompensas y reconocimientos son distribuidos en forma justa | I38: =IF(D38="X","N",IF(E38="X","CN",IF(F38="X","AV",IF(G38="X","CS",IF(H38="X","S","")))))
A39: TOMA DE DECISIONES | B39: 35 | C39: Ante algún problema o conflicto presentado mi jefe inmediato trata de obtener información antes de tomar una decisión | I39: =IF(D39="X","N",IF(E39="X","CN",IF(F39="X","AV",IF(G39="X","CS",IF(H39="X","S","")))))
B40: 36 | C40: Considero que se puede participar en la definición de los objetivos y las acciones para lograrlo | I40: =IF(D40="X","N",IF(E40="X","CN",IF(F40="X","AV",IF(G40="X","CS",IF(H40="X","S","")))))
B41: 37 | C41: En DACHSAC puedo participar en la toma de decisiones | I41: =IF(D41="X","N",IF(E41="X","CN",IF(F41="X","AV",IF(G41="X","CS",IF(H41="X","S","")))))
...

Sheet RESPUESTAS
A1: ENCUESTA DE CLIMA LABORAL
A3: INGRESO DE DATOS | J3: TOTAL CUESTIONARIOS DIGITADOS | L3: =COUNTA(E7:E136) -> 130
J5: P1 | K5: P2 | L5: P3 | M5: P4 | N5: P5 | O5: P6 | P5: P7 | Q5: P8 | R5: P9 | S5: P10 | T5: P11 | U5: P12 | V5: P13 | W5: P14 | X5: P15 | Y5: P16 | Z5: P17 | AA5: P18 | AB5: P19 | AC5: P20 | AD5: P21 | AE5: P22 | AF5: P23 | AG5: P24 | AH5: P25 | AI5: P26 | AJ5: P27 | AK5: P28 | AL5: P29 | AM5: P30 | AN5: P31 | AO5: P32 | AP5: P33 | AQ5: P34 | AR5: P35 | AS5: P36 | AT5: P37 | AU5: P38 | AV5: P39 | AW5: P40 | AX5: P41 | AY5: P42 | AZ5: P43 | BA5: P44 | BB5: P45 | BC5: P46 | BD5: P47 | BE5: P48 | BF5: P49 | BG5: P50
A6: N° | B6: Marca temporal | C6: SEDE | D6: ÁREA: | E6: PUESTO: | F6: ¿Cuánto tiempo lleva trabajando en la empresa? | G6: SEXO | H6: EDAD | I6: Me veo trabajando en DACHASAC a lo largo de… | J6: Al finalizar mi jornada diaria, me siento satisfecho con el trabajo que realizo | K6: DACHASAC facilita mi trabajo al ofrecer normas claras y procedimientos simples que son fáciles de seguir, lo que me permite realizar mis tareas con mayor rapidez y precisión. | L6: Conozco las tareas o funciones específicas que debo realizar en DACHASAC | M6: En mi equipo de trabajo, puedo expresar mi punto de vista, aun cuando contradiga al de los demás miembros | N6: Cuento con la colaboración de mis compañeros de área y de otras áreas cuando lo necesito | O6: Tienes una relación sólida y una competencia sana dentro de tu equipo | P6: El trabajo que realizo es valorado por mi jefe inmediato y recibo retroalimentación y/o capacitación constante para mejorar mi desempeño | Q6: Mi jefe inmediato se preocupa por crear un ambiente laboral agradable, lo que me motiva a mejorar día a día | R6: Me gusta lo que hago, me siento motivado a mejorar y mi trabajo me permite desarrollar al máximo mis capacidades | S6: Mi jefe inmediato me mantiene informado sobre cambios importantes del área y me brinda retroalimentación sobre mi desempeño | T6: Mi jefe inmediato escucha mis opiniones y me hace partícipe de las decisiones | U6: En DACHASAC existen suficientes canales de comunicación | V6: Las reuniones de coordinación con los miembros de otras áreas son frecuentes | W6: Las inducciones realizadas al momento de mi ingreso me ayudan a realizar las labores propias de mi puesto de trabajo | X6: DACHASAC me ofrece oportunidades para crecer profesionalmente | Y6: DACHASAC me ofrece capacitaciones y/o entrenamientos para desarrollarme profesionalmente | Z6: Mi jefe inmediato está disponible cuando lo necesito y brinda apoyo para superar los obstáculos que se presentan | AA6: Mi jefe inmediato es claro y específico al definir los objetivos de trabajo y maneja adecuadamente los conflictos | AB6: Nuestros gerentes contribuyen a crear condiciones adecuadas para el progreso de DACHASAC | AC6: Trabajo en un ambiente seguro y me siento satisfecho | AD6: Dispongo de los materiales, equipos de protección personal y recursos necesarios para realizar mi trabajo de forma segura | AE6: DACHASAC me proporciona de los equipos, herramientas y materiales a tiempo | AF6: Recibo mi remuneración a tiempo | AG6: Existe equidad en las remuneraciones | AH6: Mi remuneración es adecuada en relación con el trabajo que realizo | AI6: Mi salario y beneficios son razonables y cubren mis necesidades básicas | AJ6: Tengo la libertad de ser creativo e innovador en las soluciones de los problemas laborales que se presenten | AK6: Considero que DACHASAC es flexible y se adapta bien a los cambios, por lo que la innovación es una de sus características | AL6: Mis compañeros de trabajo toman iniciativas para la solución de problemas | AM6: Es fácil para mis compañeros de trabajo y para mí que nuestras nuevas ideas sean consideradas | AN6: Considero que los beneficios que me ofrecen en DACHASAC son los más justos y adecuados | AO6: Existen incentivos laborales para que yo trate de hacer mejor mi trabajo | AP6: Considero que cada trabajador es considerado factor clave para el éxito de DACHASAC | AQ6: Las recompensas y reconocimientos son distribuidos en forma justa | AR6: Ante algún problema o conflicto presentado mi jefe inmediato trata de obtener información antes de tomar una decisión | AS6: Considero que se puede participar en la definición de los objetivos y las acciones para lograrlo | AT6: En DACHSAC puedo participar en la toma de decisiones | AU6: Mi jefe inmediato se reúne regularmente con su equipo de trabajo a fin de coordinar nuevas soluciones a los problemas que se presentan en el trabajo | AV6: ¿Qué tan satisfecho estás de trabajar en DACHASAC? | AW6: ¿Qué tan cómodo se siente al darle sugerencias o comentarios a su jefe inmediato? | AX6: ¿Considera que todo el personal de su área se encuentra enfocada en una meta común? | AY6: ¿Considera que tiene autonomía para llevar a cabo su trabajo? | AZ6: ¿Considera que tiene la oportunidad de desarrollarse profesionalmente en DACHASAC? | BA6: ¿Qué tan probable es que usted recomiende a sus amigos o colegas el trabajar para DACHASAC? | BB6: ¿En qué aspectos debería mejorar para que recomiende más a DACHASAC? ( Si es más de 1 colocar las letras) | BC6: ¿Que aspectos consideras que deberían mejorar en tu área? ( Si es más de 1 colocar las letras) | BD6: ¿Qué aspectos valoras de tu área? ( Si es más de 1 colocar las letras) | BE6: Hipotéticamente hablando, si usted fuese a renunciar mañana, ¿Cuál sería su motivo? | BF6: ¿En qué temas le gustaría recibir más capacitaciones? | BG6: ¿Qué cree que se debería hacer para que esté más motivado?
A7: 1 | B7: 45740.557 | C7: CALLAO | D7: IMPORTACIÓN | E7: LIQUIDADOR | F7: De 2 años en adelante | G7: MASCULINO | H7: De 25 a 35 años | I7: Los próximos 2 años | J7: A VECES | K7: A VECES | L7: SIEMPRE | M7: A VECES | N7: A VECES | O7: A VECES | P7: CASI NUNCA | Q7: CASI SIEMPRE | R7: A VECES | S7: A VECES | T7: CASI SIEMPRE | U7: CASI SIEMPRE | V7: A VECES | W7: A VECES | X7: CASI NUNCA | Y7: A VECES | Z7: A VECES | AA7: A VECES | AB7: A VECES | AC7: A VECES | AD7: CASI SIEMPRE | AE7: CASI SIEMPRE | AF7: A VECES | AG7: CASI NUNCA | AH7: NUNCA | AI7: NUNCA | AJ7: A VECES | AK7: CASI SIEMPRE | AL7: CASI NUNCA | AM7: A VECES | AN7: A VECES | AO7: NUNCA | AP7: CASI SIEMPRE | AQ7: NUNCA | AR7: CASI SIEMPRE | AS7: A VECES | AT7: A VECES | AU7: CASI SIEMPRE | AV7: 6 | AW7: 6 | AX7: 6 | AY7: 6 | AZ7: 4 | BA7: 7 | BB7: Ñ) Estabilidad laboral | BC7: D) Ambiente de trabajo | BD7: B) Compañerismo entre los miembros del equipo | BE7: sueldo | BF7: partidas arancelarias , nomeclatura | BG7: llevo 4 años en la agencia con el mismo sueldo , subirme el sueldo
A8: 2 | B8: 45740.557 | C8: CALLAO | D8: EXPORTACIÓN | E8: AUXILIAR | F8: Menos de 6 meses | G8: MASCULINO | H8: Menor a 25 años | I8: Este año | J8: SIEMPRE | K8: SIEMPRE | L8: SIEMPRE | M8: CASI SIEMPRE | N8: CASI SIEMPRE | O8: CASI SIEMPRE | P8: SIEMPRE | Q8: SIEMPRE | R8: SIEMPRE | S8: SIEMPRE | T8: SIEMPRE | U8: CASI SIEMPRE | V8: CASI SIEMPRE | W8: SIEMPRE | X8: SIEMPRE | Y8: SIEMPRE | Z8: SIEMPRE | AA8: SIEMPRE | AB8: SIEMPRE | AC8: CASI SIEMPRE | AD8: SIEMPRE | AE8: SIEMPRE | AF8: CASI SIEMPRE | AG8: CASI SIEMPRE | AH8: CASI SIEMPRE | AI8: CASI SIEMPRE | AJ8: SIEMPRE | AK8: SIEMPRE | AL8: CASI SIEMPRE | AM8: CASI SIEMPRE | AN8: CASI SIEMPRE | AO8: SIEMPRE | AP8: SIEMPRE | AQ8: SIEMPRE | AR8: SIEMPRE | AS8: SIEMPRE | AT8: A VECES | AU8: SIEMPRE | AV8: 9 | AW8: 10 | AX8: 3 | AY8: 10 | AZ8: 10 | BA8: 9 | BB8: B) Relación con mis compañeros de trabajo | BC8: B) Compañerismo entre los miembros del equipo | BD8: K) Tener un trato justo al colaborador sin importar edad, genero ni el puesto | BE8: Estudios | BF8: . | BG8: .
A9: 3 | B9: 45740.562 | C9: CALLAO | D9: IMPORTACIÓN | E9: SECTORISTA | F9: De 2 años en adelante | G9: MASCULINO | H9: De 25 a 35 años | I9: Este año | J9: SIEMPRE | K9: NUNCA | L9: SIEMPRE | M9: NUNCA | N9: CASI SIEMPRE | O9: CASI SIEMPRE | P9: NUNCA | Q9: NUNCA | R9: SIEMPRE | S9: NUNCA | T9: NUNCA | U9: NUNCA | V9: NUNCA | W9: NUNCA | X9: NUNCA | Y9: NUNCA | Z9: NUNCA | AA9: NUNCA | AB9: NUNCA | AC9: NUNCA | AD9: CASI SIEMPRE | AE9: CASI SIEMPRE | AF9: CASI SIEMPRE | AG9: NUNCA | AH9: NUNCA | AI9: NUNCA | AJ9: NUNCA | AK9: NUNCA | AL9: CASI SIEMPRE | AM9: NUNCA | AN9: NUNCA | AO9: NUNCA | AP9: SIEMPRE | AQ9: NUNCA | AR9: CASI NUNCA | AS9: NUNCA | AT9: NUNCA | AU9: CASI NUNCA | AV9: 0 | AW9: 0 | AX9: 5 | AY9: 10 | AZ9: 0 | BA9: 0 | BB9: H) Liderazgo organizacional | BC9: G) Horarios y jornada laboral | BD9: A) Ningún aspecto para valorar | BE9: principalmente por la falta de un ambiente de trabajo positivo y de apoyo. Creo que un entorno donde se valore el crecimiento, la comunicación efectiva y el respeto mutuo es clave para seguir aportando lo mejor de mí | BF9: sobre mi area, actualizaciones! | BG9: para estar más motivado, creo que sería importante sentir que mi esfuerzo es reconocido y valorado. También un ambiente de trabajo positivo, donde haya buena comunicación y respeto, hace una gran diferencia. Y, por supuesto, un pago justo que refleje el trabajo que realizo sería un factor clave para seguir dando lo mejor de mí.
A10: 4 | B10: 45740.564 | C10: CALLAO | D10: SISTEMAS | E10: JEFE | F10: De 2 años en adelante | G10: MASCULINO | H10: De 25 a 35 años | I10: Los próximos 10 años en adelante | J10: A VECES | K10: CASI NUNCA | L10: SIEMPRE | M10: SIEMPRE | N10: A VECES | O10: SIEMPRE | P10: SIEMPRE | Q10: SIEMPRE | R10: SIEMPRE | S10: SIEMPRE | T10: SIEMPRE | U10: CASI NUNCA | V10: A VECES | W10: NUNCA | X10: SIEMPRE | Y10: CASI SIEMPRE | Z10: SIEMPRE | AA10: A VECES | AB10: CASI NUNCA | AC10: A VECES | AD10: SIEMPRE | AE10: SIEMPRE | AF10: CASI SIEMPRE | AG10: SIEMPRE | AH10: NUNCA | AI10: CASI NUNCA | AJ10: SIEMPRE | AK10: SIEMPRE | AL10: SIEMPRE | AM10: SIEMPRE | AN10: NUNCA | AO10: CASI SIEMPRE | AP10: CASI NUNCA | AQ10: CASI SIEMPRE | AR10: SIEMPRE | AS10: SIEMPRE | AT10: SIEMPRE | AU10: SIEMPRE | AV10: 9 | AW10: 10 | AX10: 10 | AY10: 10 | AZ10: 10 | BA10: 5 | BB10: sueldo mas acorde a especilistas de sistema segun el mercado | BC10: sueldo mas acorde a especilistas de sistema segun el mercado | BD10: b,g,h | BE10: mejora de salariario acorde a especilistas de sistemas en el mercado. | BF10: desarrollo / gestion de proyectos | BG10: viernes de casual de chela, donde la empresa invite una chela a los colaboradores, o mas afther office como los que hicieron en salaverry.
A11: 5 | B11: 45740.572 | C11: CALLAO | D11: POST - EMBARQUE | E11: COORDINADOR | F11: De 2 años en adelante | G11: MASCULINO | H11: De 36a 45 años | I11: Los próximos 3 a 5 años | J11: SIEMPRE | K11: A VECES | L11: SIEMPRE | M11: CASI SIEMPRE | N11: SIEMPRE | O11: SIEMPRE | P11: A VECES | Q11: SIEMPRE | R11: A VECES | S11: SIEMPRE | T11: SIEMPRE | U11: SIEMPRE | V11: CASI NUNCA | W11: CASI SIEMPRE | X11: CASI NUNCA | Y11: CASI NUNCA | Z11: SIEMPRE | AA11: SIEMPRE | AB11: CASI NUNCA | AC11: A VECES | AD11: CASI SIEMPRE | AE11: CASI SIEMPRE | AF11: CASI SIEMPRE | AG11: CASI NUNCA | AH11: CASI NUNCA | AI11: CASI NUNCA | AJ11: SIEMPRE | AK11: A VECES | AL11: CASI SIEMPRE | AM11: CASI SIEMPRE | AN11: A VECES | AO11: NUNCA | AP11: A VECES | AQ11: A VECES | AR11: SIEMPRE | AS11: CASI SIEMPRE | AT11: A VECES | AU11: CASI SIEMPRE | AV11: 6 | AW11: 10 | AX11: 6 | AY11: 9 | AZ11: 4 | BA11: 4 | BB11: D, E, G, L, M, Ñ, P | BC11: C) Posibilidad de aprender, retos profesionales | BD11: K) Tener un trato justo al colaborador sin importar edad, genero ni el puesto | BE11: Mejor oferta laboral | BF11: Logistica internacional | BG11: Bonos
A12: 6 | B12: 45740.609 | C12: CALLAO | D12: IMPORTACIÓN | E12: SECTORISTA | F12: De 2 años en adelante | G12: MASCULINO | H12: De 25 a 35 años | I12: Los próximos 3 a 5 años | J12: SIEMPRE | K12: A VECES | L12: A VECES | M12: CASI SIEMPRE | N12: CASI SIEMPRE | O12: CASI SIEMPRE | P12: CASI SIEMPRE | Q12: CASI SIEMPRE | R12: A VECES | S12: CASI SIEMPRE | T12: CASI SIEMPRE | U12: CASI NUNCA | V12: CASI SIEMPRE | W12: NUNCA | X12: NUNCA | Y12: NUNCA | Z12: CASI SIEMPRE | AA12: CASI SIEMPRE | AB12: NUNCA | AC12: NUNCA | AD12: CASI SIEMPRE | AE12: CASI SIEMPRE | AF12: A VECES | AG12: CASI NUNCA | AH12: NUNCA | AI12: NUNCA | AJ12: NUNCA | AK12: A VECES | AL12: CASI SIEMPRE | AM12: A VECES | AN12: CASI NUNCA | AO12: NUNCA | AP12: CASI SIEMPRE | AQ12: NUNCA | AR12: CASI SIEMPRE | AS12: CASI SIEMPRE | AT12: CASI SIEMPRE | AU12: SIEMPRE | AV12: 3 | AW12: 9 | AX12: 8 | AY12: 8 | AZ12: 1 | BA12: 0 | BB12: A / B / C / D / E / G / H / L / M / Ñ | BC12: B | BD12: G) Relación con mi jefe | BE12: REMUNERACION | BF12: EN GENERAL | BG12: MEJORAR REMUNERACION DE ACORDE AL MERCADO Y CUMPLIR CON LOS HORARIOS LABORALES Y DE HABER ALGUNA EMERGENCIA QUE REQUIERE CONECTARSE FUERA DEL HORARIO LABORAL DEBERIA HABER PAGO POR HORAS EXTRAS
A13: 7 | B13: 45740.825 | C13: CALLAO | D13: EXPORTACIÓN | E13: ASISTENTE | F13: De 2 años en adelante | G13: MASCULINO | H13: De 36a 45 años | I13: Los próximos 3 a 5 años | J13: SIEMPRE | K13: CASI SIEMPRE | L13: SIEMPRE | M13: SIEMPRE | N13: A VECES | O13: SIEMPRE | P13: SIEMPRE | Q13: SIEMPRE | R13: SIEMPRE | S13: SIEMPRE | T13: SIEMPRE | U13: SIEMPRE | V13: CASI SIEMPRE | W13: SIEMPRE | X13: SIEMPRE | Y13: SIEMPRE | Z13: SIEMPRE | AA13: SIEMPRE | AB13: SIEMPRE | AC13: SIEMPRE | AD13: SIEMPRE | AE13: SIEMPRE | AF13: CASI SIEMPRE | AG13: SIEMPRE | AH13: SIEMPRE | AI13: CASI SIEMPRE | AJ13: SIEMPRE | AK13: SIEMPRE | AL13: CASI SIEMPRE | AM13: SIEMPRE | AN13: SIEMPRE | AO13: SIEMPRE | AP13: CASI SIEMPRE | AQ13: SIEMPRE | AR13: SIEMPRE | AS13: SIEMPRE | AT13: SIEMPRE | AU13: SIEMPRE | AV13: 9 | AW13: 10 | AX13: 8 | AY13: 9 | AZ13: 10 | BA13: 10 | BB13: Ñ) Estabilidad laboral | BC13: F) La comunicación entre los miembros del equipo a todo nivel, sin importar el puesto | BD13: G) Relación con mi jefe | BE13: Mejora salarial | BF13: Sobre procedimientos | BG13: Apoyo en el turno
A14: 8 | B14: 45741.394 | C14: CALLAO | D14: IMPORTACIÓN | E14: SECTORISTA | F14: 1 año - 2 años | G14: MASCULINO | H14: De 36a 45 años | I14: Los próximos 3 a 5 años | J14: SIEMPRE | K14: A VECES | L14: CASI SIEMPRE | M14: CASI SIEMPRE | N14: CASI NUNCA | O14: A VECES | P14: A VECES | Q14: SIEMPRE | R14: CASI SIEMPRE | S14: A VECES | T14: CASI SIEMPRE | U14: CASI NUNCA | V14: NUNCA | W14: NUNCA | X14: A VECES | Y14: CASI NUNCA | Z14: CASI SIEMPRE | AA14: CASI SIEMPRE | AB14: CASI SIEMPRE | AC14: CASI SIEMPRE | AD14: CASI SIEMPRE | AE14: CASI SIEMPRE | AF14: A VECES | AG14: CASI NUNCA | AH14: NUNCA | AI14: NUNCA | AJ14: CASI SIEMPRE | AK14: CASI SIEMPRE | AL14: NUNCA | AM14: CASI NUNCA | AN14: A VECES | AO14: NUNCA | AP14: A VECES | AQ14: NUNCA | AR14: CASI SIEMPRE | AS14: CASI SIEMPRE | AT14: A VECES | AU14: A VECES | AV14: 8 | AW14: 8 | AX14: 5 | AY14: 8 | AZ14: 7 | BA14: 8 | BB14: C, G, L, P, Ñ | BC14: B, F, G, D | BD14: K) Tener un trato justo al colaborador sin importar edad, genero ni el puesto | BE14: UNA MEJORA SALARIAL | BF14: LEGISLACION ADUANERA Y SUS CAMBIOS | BG14: UNA MEJORA SALARIAL Y BENEFICIOS COMO BONOS SODEXO Y DESCUENTOS EN ESTABLECIMIENTOS
A15: 9 | B15: 45741.396 | C15: CALLAO | D15: EXPORTACIÓN | E15: AUXILIAR | F15: Menos de 6 meses | G15: MASCULINO | H15: De 25 a 35 años | I15: Los próximos 6 a 10 años | J15: CASI SIEMPRE | K15: CASI SIEMPRE | L15: CASI SIEMPRE | M15: CASI SIEMPRE | N15: CASI SIEMPRE | O15: CASI SIEMPRE | P15: CASI SIEMPRE | Q15: CASI SIEMPRE | R15: CASI SIEMPRE | S15: CASI SIEMPRE | T15: CASI SIEMPRE | U15: CASI SIEMPRE | V15: CASI SIEMPRE | W15: CASI SIEMPRE | X15: CASI SIEMPRE | Y15: CASI SIEMPRE | Z15: CASI SIEMPRE | AA15: CASI SIEMPRE | AB15: CASI SIEMPRE | AC15: CASI SIEMPRE | AD15: CASI SIEMPRE | AE15: CASI SIEMPRE | AF15: SIEMPRE | AG15: CASI SIEMPRE | AH15: A VECES | AI15: A VECES | AJ15: CASI SIEMPRE | AK15: CASI SIEMPRE | AL15: A VECES | AM15: CASI SIEMPRE | AN15: CASI SIEMPRE | AO15: SIEMPRE | AP15: CASI SIEMPRE | AQ15: CASI SIEMPRE | AR15: CASI SIEMPRE | AS15: CASI SIEMPRE | AT15: CASI SIEMPRE | AU15: CASI SIEMPRE | AV15: 8 | AW15: 8 | AX15: 8 | AY15: 8 | AZ15: 8 | BA15: 8 | BB15: L) Beneficios no remunerativos | BC15: B) Compañerismo entre los miembros del equipo | BD15: J) Enfocarse en brindar la mejor experiencia a nuestros clientes internos y externos | BE15: Una mejor oferta laboral (economía o profesional) | BF15: Aduanas | BG15: Beneficios
A16: 10 | B16: 45741.402 | C16: CALLAO | D16: CONTABILIDAD | E16: ASISTENTE | F16: De 2 años en adelante | G16: FEMENINO | H16: De 25 a 35 años | I16: Este año | J16: CASI SIEMPRE | K16: A VECES | L16: CASI SIEMPRE | M16: CASI SIEMPRE | N16: A VECES | O16: CASI SIEMPRE | P16: A VECES | Q16: A VECES | R16: CASI SIEMPRE | S16: A VECES | T16: A VECES | U16: A VECES | V16: CASI NUNCA | W16: A VECES | X16: CASI NUNCA | Y16: NUNCA | Z16: CASI NUNCA | AA16: A VECES | AB16: A VECES | AC16: CASI SIEMPRE | AD16: CASI SIEMPRE | AE16: CASI SIEMPRE | AF16: CASI SIEMPRE | AG16: A VECES | AH16: A VECES | AI16: A VECES | AJ16: A VECES | AK16: A VECES | AL16: CASI SIEMPRE | AM16: CASI SIEMPRE | AN16: A VECES | AO16: CASI NUNCA | AP16: A VECES | AQ16: A VECES | AR16: A VECES | AS16: CASI SIEMPRE | AT16: A VECES | AU16: CASI NUNCA | AV16: 7 | AW16: 7 | AX16: 8 | AY16: 8 | AZ16: 5 | BA16: 5 | BB16: que haya mas interaccion directa con gerencia para que los colaboradores den su punto de vista directa ante cualquier problema que pueda existir. | BC16: que se trate a todo los trabajadores por igual, respecto a permisos o llamadas de atencion. | BD16: H) La comunicación entre los miembros del equipo es fluida a todo nivel, sin importar puesto | BE16: La sobrecarga de trabajo. | BF16: En comercio internacional. | BG16: Que si el personal labora mas horas sean pagadas de acuerdo a ley, que haya actividades externas para fomentar la integración entre compañeros y si hay algún inconveniente u observación al personal sea investigado a fondo a fin de que a todos se les haga cumplir con multas o sanciones equitativamente.
A17: 11 | B17: 45741.403 | C17: CALLAO | D17: IMPORTACIÓN | E17: LIQUIDADOR | F17: De 2 años en adelante | G17: MASCULINO | H17: De 25 a 35 años | I17: Este año | J17: SIEMPRE | K17: NUNCA | L17: SIEMPRE | M17: NUNCA | N17: NUNCA | O17: NUNCA | P17: NUNCA | Q17: CASI NUNCA | R17: A VECES | S17: A VECES | T17: A VECES | U17: CASI NUNCA | V17: NUNCA | W17: NUNCA | X17: NUNCA | Y17: NUNCA | Z17: A VECES | AA17: CASI SIEMPRE | AB17: NUNCA | AC17: NUNCA | AD17: CASI SIEMPRE | AE17: CASI SIEMPRE | AF17: NUNCA | AG17: NUNCA | AH17: NUNCA | AI17: NUNCA | AJ17: SIEMPRE | AK17: NUNCA | AL17: NUNCA | AM17: NUNCA | AN17: NUNCA | AO17: NUNCA | AP17: CASI NUNCA | AQ17: NUNCA | AR17: CASI SIEMPRE | AS17: A VECES | AT17: CASI NUNCA | AU17: CASI NUNCA | AV17: 1 | AW17: 3 | AX17: 3 | AY17: 0 | AZ17: 1 | BA17: 1 | BB17: G) Reconocimiento | BC17: RECONOCIMIENTO | BD17: A) Ningún aspecto para valorar | BE17: No reconocen a un buen trabajador como debería ser. | BF17: Leyes aduaneras | BG17: RECONOCIMIENTO
A18: 12 | B18: 45741.406 | C18: CHIMBOTE | D18: ADMINISTRACIÓN | E18: ADMINISTRADOR | F18: De 2 años en adelante | G18: MASCULINO | H18: De 36a 45 años | I18: Los próximos 10 años en adelante | J18: SIEMPRE | K18: CASI SIEMPRE | L18: SIEMPRE | M18: CASI SIEMPRE | N18: A VECES | O18: SIEMPRE | P18: CASI SIEMPRE | Q18: CASI SIEMPRE | R18: SIEMPRE | S18: CASI SIEMPRE | T18: SIEMPRE | U18: SIEMPRE | V18: CASI SIEMPRE | W18: SIEMPRE | X18: SIEMPRE | Y18: SIEMPRE | Z18: CASI SIEMPRE | AA18: SIEMPRE | AB18: SIEMPRE | AC18: SIEMPRE | AD18: SIEMPRE | AE18: SIEMPRE | AF18: SIEMPRE | AG18: CASI SIEMPRE | AH18: CASI SIEMPRE | AI18: CASI SIEMPRE | AJ18: SIEMPRE | AK18: SIEMPRE | AL18: SIEMPRE | AM18: SIEMPRE | AN18: CASI SIEMPRE | AO18: NUNCA | AP18: SIEMPRE | AQ18: CASI NUNCA | AR18: SIEMPRE | AS18: SIEMPRE | AT18: CASI SIEMPRE | AU18: SIEMPRE | AV18: 9 | AW18: 10 | AX18: 10 | AY18: 9 | AZ18: 10 | BA18: 10 | BB18: A, B, C, G, H, L, M, N. | BC18: B, C, F, G, H, I. | BD18: C, D, G. | BE18: Edad máxima. | BF18: Aduaneras, por mi puesto de trabajo. | BG18: Descansos respectivos por acumulación de HHEE, si en caso no es remunerado.
... A136: 130 | B136: 45747.489 | C136: CALLAO | D136: EXPORTACIÓN | E136: COORDINADOR | F136: De 2 años en adelante | G136: MASCULINO | H136: De 36a 45 años | I136: Los próximos 10 años en adelante | J136: SIEMPRE | K136: SIEMPRE | L136: SIEMPRE | M136: CASI SIEMPRE | N136: CASI SIEMPRE | O136: SIEMPRE | P136: CASI SIEMPRE | Q136: NUNCA | R136: SIEMPRE | S136: A VECES | T136: CASI SIEMPRE | U136: CASI SIEMPRE | V136: NUNCA | W136: SIEMPRE | X136: SIEMPRE | Y136: NUNCA | Z136: NUNCA | AA136: A VECES | AB136: SIEMPRE | AC136: CASI SIEMPRE | AD136: SIEMPRE | AE136: SIEMPRE | AF136: CASI SIEMPRE | AG136: CASI SIEMPRE | AH136: CASI SIEMPRE | AI136: CASI SIEMPRE | AJ136: SIEMPRE | AK136: SIEMPRE | AL136: SIEMPRE | AM136: SIEMPRE | AN136: CASI SIEMPRE | AO136: CASI SIEMPRE | AP136: CASI SIEMPRE | AQ136: CASI SIEMPRE | AR136: NUNCA | AS136: CASI SIEMPRE | AT136: SIEMPRE | AU136: A VECES | AV136: 9 | AW136: 2 | AX136: 10 | AY136: 10 | AZ136: 10 | BA136: 8 | BB136: L) Beneficios no remunerativos | BC136: I) Tener un trato justo al colaborador sin importar edad, genero ni el puesto | BD136: E) Reconocimiento | BE136: Personales | BF136: Aduanas | BG136: todo bien con tal de darle solución algún trabajo encomendado .
B138: NUNCA | D138: CASI NUNCA | E138: A VECES | F138: CASI SIEMPRE | G138: SIEMPRE
B139: 1 | D139: 2 | E139: 3 | F139: 4 | G139: 5
D140: GENERALIDADES | E140: GENERALIDADES | F140: GENERALIDADES | G140: COLABORACIÓN | H140: COLABORACIÓN | I140: COLABORACIÓN | J140: VALORACIÓN - MOTIVACIÓN | K140: VALORACIÓN - MOTIVACIÓN | L140: VALORACIÓN - MOTIVACIÓN | M140: COMUNICACIÓN | N140: COMUNICACIÓN | O140: COMUNICACIÓN | P140: COMUNICACIÓN | Q140: FORMACIÓN | R140: FORMACIÓN | S140: FORMACIÓN | T140: LIDERAZGO | U140: LIDERAZGO | V140: LIDERAZGO | W140: SEGURIDAD | X140: SEGURIDAD | Y140: SEGURIDAD | Z140: REMUNERACIÓN | AA140: REMUNERACIÓN | AB140: REMUNERACIÓN | AC140: REMUNERACIÓN | AD140: INNOVACIÓN | AE140: INNOVACIÓN | AF140: INNOVACIÓN | AG140: INNOVACIÓN | AH140: RECOMPENSA | AI140: RECOMPENSA | AJ140: RECOMPENSA | AK140: RECOMPENSA | AL140: TOMA DE DECISIONES | AM140: TOMA DE DECISIONES | AN140: TOMA DE DECISIONES | AO140: TOMA DE DECISIONES
D141: P1 | E141: P2 | F141: P3 | G141: P4 | H141: P5 | I141: P6 | J141: P7 | K141: P8 | L141: P9 | M141: P10 | N141: P11 | O141: P12 | P141: P13 | Q141: P14 | R141: P15 | S141: P16 | T141: P17 | U141: P18 | V141: P19 | W141: P20 | X141: P21 | Y141: P22 | Z141: P23 | AA141: P24 | AB141: P25 | AC141: P26 | AD141: P27 | AE141: P28 | AF141: P29 | AG141: P30 | AH141: P31 | AI141: P32 | AJ141: P33 | AK141: P34 | AL141: P35 | AM141: P36 | AN141: P37 | AO141: P38 | AP141: TOTAL DE RESPUESTAS POR PREGUNTA
B142: NUNCA | D142: =COUNTIF(J7:J136,$B$142)*1 -> 0 | E142: =COUNTIF(K7:K136,$B$142)*1 -> 3 | F142: =COUNTIF(L7:L136,$B$142)*1 -> 0 | G142: =COUNTIF(M7:M136,$B$142)*1 -> 3 | H142: =COUNTIF(N7:N136,$B$142)*1 -> 1 | I142: =COUNTIF(O7:O136,$B$142)*1 -> 3 | J142: =COUNTIF(P7:P136,$B$142)*1 -> 5 | K142: =COUNTIF(Q7:Q136,$B$142)*1 -> 3 | ... AO142: =COUNTIF(AU7:AU136,$B$142)*1 -> 12 | AP142: =SUM(C142:AO142)/1 -> 267
B143: CASI NUNCA | D143: =COUNTIF(J7:J136,$B$143)*2 -> 0 | E143: =COUNTIF(K7:K136,$B$143)*2 -> 6 | F143: =COUNTIF(L7:L136,$B$143)*2 -> 0 | G143: =COUNTIF(M7:M136,$B$143)*2 -> 4 | H143: =COUNTIF(N7:N136,$B$143)*2 -> 6 | I143: =COUNTIF(O7:O136,$B$143)*2 -> 2 | J143: =COUNTIF(P7:P136,$B$143)*2 -> 20 | K143: =COUNTIF(Q7:Q136,$B$143)*2 -> 20 | ... AO143: =COUNTIF(AU7:AU136,$B$143)*2 -> 22 | AP143: =SUM(C143:AO143)/2 -> 376
B144: A VECES | D144: =COUNTIF(J7:J136,$B$144)*3 -> 36 | E144: =COUNTIF(K7:K136,$B$144)*3 -> 84 | F144: =COUNTIF(L7:L136,$B$144)*3 -> 15 | G144: =COUNTIF(M7:M136,$B$144)*3 -> 69 | H144: =COUNTIF(N7:N136,$B$144)*3 -> 60 | I144: =COUNTIF(O7:O136,$B$144)*3 -> 21 | J144: =COUNTIF(P7:P136,$B$144)*3 -> 99 | K144: =COUNTIF(Q7:Q136,$B$144)*3 -> 66 | ... AO144: =COUNTIF(AU7:AU136,$B$144)*3 -> 60 | AP144: =SUM(C144:AO144)/3 -> 941
B145: CASI SIEMPRE | D145: =COUNTIF(J7:J136,$B$145)*4 -> 184 | E145: =COUNTIF(K7:K136,$B$145)*4 -> 196 | F145: =COUNTIF(L7:L136,$B$145)*4 -> 104 | G145: =COUNTIF(M7:M136,$B$145)*4 -> 176 | H145: =COUNTIF(N7:N136,$B$145)*4 -> 204 | I145: =COUNTIF(O7:O136,$B$145)*4 -> 200 | J145: =COUNTIF(P7:P136,$B$145)*4 -> 148 | K145: =COUNTIF(Q7:Q136,$B$145)*4 -> 172 | ... AO145: =COUNTIF(AU7:AU136,$B$145)*4 -> 160 | AP145: =SUM(C145:AO145)/4 -> 1565
B146: SIEMPRE | D146: =COUNTIF(J7:J136,$B$146)*5 -> 360 | E146: =COUNTIF(K7:K136,$B$146)*5 -> 235 | F146: =COUNTIF(L7:L136,$B$146)*5 -> 495 | G146: =COUNTIF(M7:M136,$B$146)*5 -> 290 | H146: =COUNTIF(N7:N136,$B$146)*5 -> 275 | I146: =COUNTIF(O7:O136,$B$146)*5 -> 345 | J146: =COUNTIF(P7:P136,$B$146)*5 -> 225 | K146: =COUNTIF(Q7:Q136,$B$146)*5 -> 260 | ... AO146: =COUNTIF(AU7:AU136,$B$146)*5 -> 235 | AP146: =SUM(C146:AO146)/5 -> 1791
B147: TOTAL | D147: =SUM(D142:D146) -> 580 | E147: =SUM(E142:E146) -> 524 | F147: =SUM(F142:F146) -> 614 | G147: =SUM(G142:G146) -> 542 | H147: =SUM(H142:H146) -> 546 | I147: =SUM(I142:I146) -> 571 | J147: =SUM(J142:J146) -> 497 | K147: =SUM(K142:K146) -> 521 | ... AP147: =SUM(AP142:AP146) -> 4940
D150: P39 | E150: P40 | F150: P41 | G150: P42 | H150: P43 | I150: P44 | J150: TOTAL DE RESPUESTAS
B151: 1 | D151: =COUNTIF(AV7:AV136,$B$151)*$B$151 -> 2 | E151: =COUNTIF(AW7:AW136,$B$151)*$B$151 -> 2 | F151: =COUNTIF(AX7:AX136,$B$151)*$B$151 -> 0 | G151: =COUNTIF(AY7:AY136,$B$151)*$B$151 -> 0 | H151: =COUNTIF(AZ7:AZ136,$B$151)*$B$151 -> 3 | I151: =COUNTIF(BA7:BA136,$B$151)*$B$151 -> 2 | J151: =SUM(D151:I151)/B151 -> 9
B152: 2 | D152: =COUNTIF(AV7:AV136,$B$152)*$B$152 -> 4 | E152: =COUNTIF(AW7:AW136,$B$152)*$B$152 -> 6 | F152: =COUNTIF(AX7:AX136,$B$152)*$B$152 -> 2 | G152: =COUNTIF(AY7:AY136,$B$152)*$B$152 -> 2 | H152: =COUNTIF(AZ7:AZ136,$B$152)*$B$152 -> 6 | I152: =COUNTIF(BA7:BA136,$B$152)*$B$152 -> 10 | J152: =SUM(D152:I152)/B152 -> 15
B153: 3 | D153: =COUNTIF(AV7:AV136,$B$153)*$B$153 -> 9 | E153: =COUNTIF(AW7:AW136,$B$153)*$B$153 -> 12 | F153: =COUNTIF(AX7:AX136,$B$153)*$B$153 -> 12 | G153: =COUNTIF(AY7:AY136,$B$153)*$B$153 -> 0 | H153: =COUNTIF(AZ7:AZ136,$B$153)*$B$153 -> 9 | I153: =COUNTIF(BA7:BA136,$B$153)*$B$153 -> 6 | J153: =SUM(D153:I153)/B153 -> 16
B154: 4 | D154: =COUNTIF(AV7:AV136, $B$154)*$B$154 -> 16 | E154: =COUNTIF(AW7:AW136, $B$154)*$B$154 -> 32 | F154: =COUNTIF(AX7:AX136, $B$154)*$B$154 -> 20 | G154: =COUNTIF(AY7:AY136, $B$154)*$B$154 -> 4 | H154: =COUNTIF(AZ7:AZ136, $B$154)*$B$154 -> 24 | I154: =COUNTIF(BA7:BA136, $B$154)*$B$154 -> 16 | J154: =SUM(D154:I154)/B154 -> 28
B155: 5 | D155: =COUNTIF(AV7:AV136,$B$155)*$B$155 -> 45 | E155: =COUNTIF(AW7:AW136,$B$155)*$B$155 -> 60 | F155: =COUNTIF(AX7:AX136,$B$155)*$B$155 -> 45 | G155: =COUNTIF(AY7:AY136,$B$155)*$B$155 -> 20 | H155: =COUNTIF(AZ7:AZ136,$B$155)*$B$155 -> 50 | I155: =COUNTIF(BA7:BA136,$B$155)*$B$155 -> 65 | J155: =SUM(D155:I155)/B155 -> 57
B156: 6 | D156: =COUNTIF(AV7:AV136,$B$156)*$B$156 -> 72 | E156: =COUNTIF(AW7:AW136,$B$156)*$B$156 -> 24 | F156: =COUNTIF(AX7:AX136,$B$156)*$B$156 -> 54 | G156: =COUNTIF(AY7:AY136,$B$156)*$B$156 -> 30 | H156: =COUNTIF(AZ7:AZ136,$B$156)*$B$156 -> 42 | I156: =COUNTIF(BA7:BA136,$B$156)*$B$156 -> 30 | J156: =SUM(D156:I156)/B156 -> 42
B157: 7 | D157: =COUNTIF(AV7:AV136,$B$157)*$B$157 -> 126 | E157: =COUNTIF(AW7:AW136,$B$157)*$B$157 -> 70 | F157: =COUNTIF(AX7:AX136,$B$157)*$B$157 -> 84 | G157: =COUNTIF(AY7:AY136,$B$157)*$B$157 -> 42 | H157: =COUNTIF(AZ7:AZ136,$B$157)*$B$157 -> 140 | I157: =COUNTIF(BA7:BA136,$B$157)*$B$157 -> 105 | J157: =SUM(D157:I157)/B157 -> 81
B158: 8 | D158: =COUNTIF(AV7:AV136,$B$158)*$B$158 -> 192 | E158: =COUNTIF(AW7:AW136,$B$158)*$B$158 -> 168 | F158: =COUNTIF(AX7:AX136,$B$158)*$B$158 -> 208 | G158: =COUNTIF(AY7:AY136,$B$158)*$B$158 -> 160 | H158: =COUNTIF(AZ7:AZ136,$B$158)*$B$158 -> 144 | I158: =COUNTIF(BA7:BA136,$B$158)*$B$158 -> 216 | J158: =SUM(D158:I158)/B158 -> 136
B159: 9 | D159: =COUNTIF(AV7:AV136,$B$159)*$B$159 -> 279 | E159: =COUNTIF(AW7:AW136,$B$159)*$B$159 -> 234 | F159: =COUNTIF(AX7:AX136,$B$159)*$B$159 -> 225 | G159: =COUNTIF(AY7:AY136,$B$159)*$B$159 -> 369 | H159: =COUNTIF(AZ7:AZ136,$B$159)*$B$159 -> 198 | I159: =COUNTIF(BA7:BA136,$B$159)*$B$159 -> 243 | J159: =SUM(D159:I159)/B159 -> 172
B160: 10 | D160: =COUNTIF(AV7:AV136,$B$160)*$B$160 -> 240 | E160: =COUNTIF(AW7:AW136,$B$160)*$B$160 -> 390 | F160: =COUNTIF(AX7:AX136,$B$160)*$B$160 -> 390 | G160: =COUNTIF(AY7:AY136,$B$160)*$B$160 -> 510 | H160: =COUNTIF(AZ7:AZ136,$B$160)*$B$160 -> 320 | I160: =COUNTIF(BA7:BA136,$B$160)*$B$160 -> 260 | J160: =SUM(D160:I160)/B160 -> 211
B161: TOTAL | D161: =SUM(D151:D160) -> 985 | E161: =SUM(E151:E160) -> 998 | F161: =SUM(F151:F160) -> 1040 | G161: =SUM(G151:G160) -> 1137 | H161: =SUM(H151:H160) -> 936 | I161: =SUM(I151:I160) -> 953 | J161: =SUM(J151:J160) -> 767
B164: TOTAL CUESTIONARIOS DIGITADOS | E164: =L3 -> 130
...

Sheet RESULTADOS 1
B2: ESTUDIO DEL CLIMA ORGANIZACIONAL
B3: RESULTADOS PREGUNTAS CERRADAS
C4: TOTAL CUESTIONARIOS DIGITADOS | J4: =RESPUESTAS!L3 -> 130
C5: Valor Promedio | J5: =AVERAGE(J9:J11) -> 77.882753
C6: RESULTADO: | J6: =IF(J5>80, "Saludable", IF(J5>50, "En Proceso de Mejora", "No Saludable")) -> En Proceso de Mejora
C8: VARIABLES | D8: Peso | E8: Num.Preg | F8: Puntaje maximo | G8: Puntaje obtenido | H8: Puntaje Maximo ajustado | I8: Puntaje Obtenido ajustado | J8: Valor Promedio
C9: Potencial Humano | D9: 40 | E9: =+SUM(E15:E18) -> 14 | F9: =SUM(H15:H18) -> 2184 | G9: =SUM(I15:I18) -> 1720.34 | H9: =IF(ISERROR(+D9*F9/100),0,ROUND(+D9*F9/100,2)) -> 873.6 | I9: =IF(ISERROR(G9*H9/F9),0,ROUND(G9*H9/F9,2)) -> 688.14 | J9: =IF(ISERROR(I9*100/H9), 0, +I9*100/H9) -> 78.770604
C10: Diseño Organizacional | D10: 25 | E10: =+SUM(E21:E24) -> 15 | F10: =SUM(H21:H24) -> 2470 | G10: =SUM(I21:I24) -> 1853.65 | H10: =IF(ISERROR(+D10*F10/100),0,ROUND(+D10*F10/100,2)) -> 617.5 | I10: =IF(ISERROR(G10*H10/F10),0,ROUND(G10*H10/F10,2)) -> 463.41 | J10: =IF(ISERROR(I10*100/H10), 0, +I10*100/H10) -> 75.046154
C11: Cultura de la Organización | D11: 35 | E11: =+SUM(E27:E29) -> 9 | F11: =SUM(H27:H29) -> 1950 | G11: =SUM(I27:I29) -> 1556.7 | H11: =IF(ISERROR(+D11*F11/100),0,ROUND(+D11*F11/100,2)) -> 682.5 | I11: =IF(ISERROR(G11*H11/F11),0,ROUND(G11*H11/F11,2)) -> 544.85 | J11: =IF(ISERROR(I11*100/H11), 0, +I11*100/H11) -> 79.831502
C13: DIMENSIONES
C14: Potencial Humano | D14: Peso | E14: Num.Preg | F14: Puntaje maximo | G14: Puntaje obtenido | H14: Puntaje Maximo ajustado | I14: Puntaje Obtenido Ajustado | J14: Valor Promedio
C15: Liderazgo | D15: 46 | E15: 3 | F15: =E15*5*$J$4 -> 1950 | G15: =+SUMIF(Dimensiones,$C15,DimenRpta) -> 1556 | H15: =IF(E15=0,0,IF(ISERROR(+D15*F15/100),0,+D15*F15/100)) -> 897 | I15: =IF(ISERROR(+G15*H15/F15),0,+G15*H15/F15) -> 715.76 | J15: =IF(ISERROR(I15*100/H15), 0, +I15*100/H15) -> 79.794872
C16: Innovación | D16: 18 | E16: 4 | F16: =E16*5*$J$4 -> 2600 | G16: =+SUMIF(Dimensiones,$C16,DimenRpta) -> 2070 | H16: =IF(E16=0,0,IF(ISERROR(+D16*F16/100),0,+D16*F16/100)) -> 468 | I16: =IF(ISERROR(+G16*H16/F16),0,+G16*H16/F16) -> 372.6 | J16: =IF(ISERROR(I16*100/H16), 0, +I16*100/H16) -> 79.615385
C17: Recompensa | D17: 18 | E17: 4 | F17: =E17*5*$J$4 -> 2600 | G17: =+SUMIF(Dimensiones,$C17,DimenRpta) -> 1793 | H17: =IF(E17=0,0,IF(ISERROR(+D17*F17/100),0,+D17*F17/100)) -> 468 | I17: =IF(ISERROR(+G17*H17/F17),0,+G17*H17/F17) -> 322.74 | J17: =IF(ISERROR(I17*100/H17), 0, +I17*100/H17) -> 68.961538
C18: Generalidades | D18: 18 | E18: 3 | F18: =E18*5*$J$4 -> 1950 | G18: =+SUMIF(Dimensiones,$C18,DimenRpta) -> 1718 | H18: =IF(E18=0,0,IF(ISERROR(+D18*F18/100),0,+D18*F18/100)) -> 351 | I18: =IF(ISERROR(+G18*H18/F18),0,+G18*H18/F18) -> 309.24 | J18: =IF(ISERROR(I18*100/H18), 0, +I18*100/H18) -> 88.102564
C20: Diseño Organizacional | D20: Peso | E20: Num.Preg | F20: Puntaje maximo | G20: Puntaje obtenido | H20: Puntaje ajustado | I20: Puntaje Obtenido Ajustado | J20: Valor Promedio
C21: Seguridad | D21: 20 | E21: 3 | F21: =E21*5*$J$4 -> 1950 | G21: =+SUMIF(Dimensiones,$C21,DimenRpta) -> 1638 | H21: =IF(E21=0,0,IF(ISERROR(+D21*F21/100),0,+D21*F21/100)) -> 390 | I21: =IF(ISERROR(+G21*H21/F21),0,+G21*H21/F21) -> 327.6 | J21: =IF(ISERROR(I21*100/H21), 0, +I21*100/H21) -> 84
C22: Toma de Decisiones | D22: 35 | E22: 4 | F22: =E22*5*$J$4 -> 2600 | G22: =+SUMIF(Dimensiones,$C22,DimenRpta) -> 1994 | H22: =IF(E22=0,0,IF(ISERROR(+D22*F22/100),0,+D22*F22/100)) -> 910 | I22: =IF(ISERROR(+G22*H22/F22),0,+G22*H22/F22) -> 697.9 | J22: =IF(ISERROR(I22*100/H22), 0, +I22*100/H22) -> 76.692308
C23: Comunicación | D23: 25 | E23: 4 | F23: =E23*5*$J$4 -> 2600 | G23: =+SUMIF(Dimensiones,$C23,DimenRpta) -> 1935 | H23: =IF(E23=0,0,IF(ISERROR(+D23*F23/100),0,+D23*F23/100)) -> 650 | I23: =IF(ISERROR(+G23*H23/F23),0,+G23*H23/F23) -> 483.75 | J23: =IF(ISERROR(I23*100/H23), 0, +I23*100/H23) -> 74.423077
C24: Remuneración | D24: 20 | E24: 4 | F24: =E24*5*$J$4 -> 2600 | G24: =+SUMIF(Dimensiones,$C24,DimenRpta) -> 1722 | H24: =IF(E24=0,0,IF(ISERROR(+D24*F24/100),0,+D24*F24/100)) -> 520 | I24: =IF(ISERROR(+G24*H24/F24),0,+G24*H24/F24) -> 344.4 | J24: =IF(ISERROR(I24*100/H24), 0, +I24*100/H24) -> 66.230769
C26: Cultura de la Organización | D26: Peso | E26: Num.Preg | F26: Puntaje maximo | G26: Puntaje obtenido | H26: Puntaje ajustado | I26: Puntaje Obtenido Ajustado | J26: Valor Promedio
C27: Formación | D27: 22 | E27: 3 | F27: =E27*5*$J$4 -> 1950 | G27: =+SUMIF(Dimensiones,$C27,DimenRpta) -> 1390 | H27: =IF(E27=0,0,IF(ISERROR(+D27*F27/100),0,+D27*F27/100)) -> 429 | I27: =IF(ISERROR(+G27*H27/F27),0,+G27*H27/F27) -> 305.8 | J27: =IF(ISERROR(I27*100/H27), 0, +I27*100/H27) -> 71.282051
C28: Colaboración | D28: 22 | E28: 3 | F28: =E28*5*$J$4 -> 1950 | G28: =+SUMIF(Dimensiones,$C28,DimenRpta) -> 1659 | H28: =IF(E28=0,0,IF(ISERROR(+D28*F28/100),0,+D28*F28/100)) -> 429 | I28: =IF(ISERROR(+G28*H28/F28),0,+G28*H28/F28) -> 364.98 | J28: =IF(ISERROR(I28*100/H28), 0, +I28*100/H28) -> 85.076923
C29: Valoración - Motivación | D29: 56 | E29: 3 | F29: =E29*5*$J$4 -> 1950 | G29: =+SUMIF(Dimensiones,$C29,DimenRpta) -> 1582 | H29: =IF(E29=0,0,IF(ISERROR(+D29*F29/100),0,+D29*F29/100)) -> 1092 | I29: =IF(ISERROR(+G29*H29/F29),0,+G29*H29/F29) -> 885.92 | J29: =IF(ISERROR(I29*100/H29), 0, +I29*100/H29) -> 81.128205

Sheet RESULTADOS 2
B2: ESTUDIO DEL CLIMA ORGANIZACIONAL
B3: RESULTADOS PREGUNTAS EN ESCALA
C4: TOTAL CUESTIONARIOS DIGITADOS | J4: =RESPUESTAS!L3 -> 130
C5: Valor Promedio | J5: =AVERAGE(J9) -> 77.184615
C6: RESULTADO: | J6: =IF(J5>80, "Saludable", IF(J5>50, "En Proceso de Mejora", "No Saludable")) -> En Proceso de Mejora
C8: VARIABLES | D8: Peso | E8: Num.Preg | F8: Puntaje maximo | G8: Puntaje obtenido | H8: Puntaje Maximo ajustado | I8: Puntaje Obtenido ajustado | J8: Valor Promedio
C9: Satisfacción | D9: 100 | E9: =+SUM(E13:E18) -> 6 | F9: =SUM(H13:H18) -> 1300 | G9: =SUM(I13:I18) -> 1003.4 | H9: =IF(ISERROR(+D9*F9/100),0,ROUND(+D9*F9/100,2)) -> 1300 | I9: =IF(ISERROR(G9*H9/F9),0,ROUND(G9*H9/F9,2)) -> 1003.4 | J9: =IF(ISERROR(I9*100/H9), 0, +I9*100/H9) -> 77.184615
C11: DIMENSIONES
C12: SATISFACCIÓN | D12: Peso | E12: Num.Preg | F12: Puntaje maximo | G12: Puntaje obtenido | H12: Puntaje Maximo ajustado | I12: Puntaje Obtenido Ajustado | J12: Valor Promedio
C13: =RESPUESTAS!AV6 -> ¿Qué tan satisfecho estás de trabajar en DACHASAC? | D13: 20 | E13: 1 | F13: =E13*10*$J$4 -> 1300 | G13: =RESPUESTAS!D161 -> 985 | H13: =IF(E13=0,0,IF(ISERROR(+D13*F13/100),0,+D13*F13/100)) -> 260 | I13: =IF(ISERROR(+G13*H13/F13),0,+G13*H13/F13) -> 197 | J13: =IF(ISERROR(I13*100/H13), 0, +I13*100/H13) -> 75.769231
C14: =RESPUESTAS!AW6 -> ¿Qué tan cómodo se siente al darle sugerencias o comentarios a su jefe inmediato? | D14: 15 | E14: 1 | F14: =E14*10*$J$4 -> 1300 | G14: =RESPUESTAS!E161 -> 998 | H14: =IF(E14=0,0,IF(ISERROR(+D14*F14/100),0,+D14*F14/100)) -> 195 | I14: =IF(ISERROR(+G14*H14/F14),0,+G14*H14/F14) -> 149.7 | J14: =IF(ISERROR(I14*100/H14), 0, +I14*100/H14) -> 76.769231
C15: =RESPUESTAS!AX6 -> ¿Considera que todo el personal de su área se encuentra enfocada en una meta común? | D15: 15 | E15: 1 | F15: =E15*10*$J$4 -> 1300 | G15: =RESPUESTAS!F161 -> 1040 | H15: =IF(E15=0,0,IF(ISERROR(+D15*F15/100),0,+D15*F15/100)) -> 195 | I15: =IF(ISERROR(+G15*H15/F15),0,+G15*H15/F15) -> 156 | J15: =IF(ISERROR(I15*100/H15), 0, +I15*100/H15) -> 80
C16: =RESPUESTAS!AY6 -> ¿Considera que tiene autonomía para llevar a cabo su trabajo? | D16: 15 | E16: 1 | F16: =E16*10*$J$4 -> 1300 | G16: =RESPUESTAS!G161 -> 1137 | H16: =IF(E16=0,0,IF(ISERROR(+D16*F16/100),0,+D16*F16/100)) -> 195 | I16: =IF(ISERROR(+G16*H16/F16),0,+G16*H16/F16) -> 170.55 | J16: =IF(ISERROR(I16*100/H16), 0, +I16*100/H16) -> 87.461538
C17: =RESPUESTAS!AZ6 -> ¿Considera que tiene la oportunidad de desarrollarse profesionalmente en DACHASAC? | D17: 20 | E17: 1 | F17: =E17*10*$J$4 -> 1300 | G17: =RESPUESTAS!H161 -> 936 | H17: =IF(E17=0,0,IF(ISERROR(+D17*F17/100),0,+D17*F17/100)) -> 260 | I17: =IF(ISERROR(+G17*H17/F17),0,+G17*H17/F17) -> 187.2 | J17: =IF(ISERROR(I17*100/H17), 0, +I17*100/H17) -> 72
C18: =RESPUESTAS!BA6 -> ¿Qué tan probable es que usted recomiende a sus amigos o colegas el trabajar para DACHASAC? | D18: 15 | E18: 1 | F18: =E18*10*$J$4 -> 1300 | G18: =RESPUESTAS!I161 -> 953 | H18: =IF(E18=0,0,IF(ISERROR(+D18*F18/100),0,+D18*F18/100)) -> 195 | I18: =IF(ISERROR(+G18*H18/F18),0,+G18*H18/F18) -> 142.95 | J18: =IF(ISERROR(I18*100/H18), 0, +I18*100/H18) -> 73.307692

Sheet COMPARATIVO
B2: GLOBAL | C2: CANT. DE ENCUESTADOS | D2: RESULTADOS PREGUNTAS CERRADAS (%) | E2: RESULTADOS PREGUNTAS EN ESCALA (%)
B3: 44713
B4: 44531
B5: 44348

Sheet P. ABIERTAS
B2: ESTUDIO DEL CLIMA ORGANIZACIONAL
B3: RESULTADOS PREGUNTAS ABIERTAS
C4: TOTAL CUESTIONARIOS DIGITADOS | D4: 130
B6: Hipotéticamente hablando, si usted fuese a renunciar mañana, ¿Cuál sería su motivo?
B7: 1 | C7: =RESPUESTAS!BE7 -> sueldo
B8: 2 | C8: =RESPUESTAS!BE8 -> Estudios
B9: 3 | C9: =RESPUESTAS!BE9 -> principalmente por la falta de un ambiente de trabajo positivo y de apoyo. Creo que un entorno donde se valore el crecimiento, la comunicación efectiva y el respeto mutuo es clave para seguir aportando lo mejor de mí
B10: 4 | C10: =RESPUESTAS!BE10 -> mejora de salariario acorde a especilistas de sistemas en el mercado.
B11: 5 | C11: =RESPUESTAS!BE11 -> Mejor oferta laboral
B12: 6 | C12: =RESPUESTAS!BE12 -> REMUNERACION
B13: 7 | C13: =RESPUESTAS!BE13 -> Mejora salarial
B14: 8 | C14: =RESPUESTAS!BE14 -> UNA MEJORA SALARIAL
B15: 9 | C15: =RESPUESTAS!BE15 -> Una mejor oferta laboral (economía o profesional)
B16: 10 | C16: =RESPUESTAS!BE16 -> La sobrecarga de trabajo.
B17: 11 | C17: =RESPUESTAS!BE17 -> No reconocen a un buen trabajador como debería ser.
B18: 12 | C18: =RESPUESTAS!BE18 -> Edad máxima.
... B136: 130 | C136: =RESPUESTAS!BE136 -> Personales
B137: 161
B138: 162
B139: 163
B140: 164
B141: 165
B142: 166
B143: 167
B144: 168
B145: 169
B146: 170
B147: 171
B148: 172
... B276: 300
B278: ¿En qué temas le gustaría recibir más capacitaciones?
B279: 1 | C279: =RESPUESTAS!BF7 -> partidas arancelarias , nomeclatura
B280: 2 | C280: =RESPUESTAS!BF8 -> .
B281: 3 | C281: =RESPUESTAS!BF9 -> sobre mi area, actualizaciones!
B282: 4 | C282: =RESPUESTAS!BF10 -> desarrollo / gestion de proyectos
B283: 5 | C283: =RESPUESTAS!BF11 -> Logistica internacional
B284: 6 | C284: =RESPUESTAS!BF12 -> EN GENERAL
B285: 7 | C285: =RESPUESTAS!BF13 -> Sobre procedimientos
B286: 8 | C286: =RESPUESTAS!BF14 -> LEGISLACION ADUANERA Y SUS CAMBIOS
B287: 9 | C287: =RESPUESTAS!BF15 -> Aduanas
...

Sheet LISTADO DE FRECUENCIAS & %
C1: LISTA DE FRECUENCIAS
C3: TOTAL CUESTIONARIOS DIGITADOS | D3: =RESPUESTAS!L3 -> 130
A4: Nº | B4: VARIABLES | C4: ITEMS | D4: NUNCA | E4: % | F4: CASI NUNCA | G4: % | H4: A VECES | I4: % | J4: CASI SIEMPRE | K4: % | L4: SIEMPRE | M4: % | N4: N° | O4: %
A5: 1 | B5: GENERALIDADES | C5: Al finalizar mi jornada diaria, me siento satisfecho con el trabajo que realizo. | D5: =RESPUESTAS!D142 -> 0 | E5: =((D5*1)/$D$3) -> 0 | F5: =RESPUESTAS!D143 -> 0 | G5: =F5*1/$D$3 -> 0 | H5: =RESPUESTAS!D144/3 -> 12 | I5: =H5*1/$D$3 -> 0.092307692 | J5: =RESPUESTAS!D145/4 -> 46 | K5: =J5*1/$D$3 -> 0.35384615 | L5: =RESPUESTAS!D146/5 -> 72 | M5: =L5*1/$D$3 -> 0.55384615 | N5: =SUM(D5+F5+H5+J5+L5) -> 130 | O5: =SUM(E5+G5+I5+K5+M5) -> 1
A6: 2 | C6: DACHASAC facilita mi trabajo al ofrecer normas claras y procedimientos simples que son fáciles de seguir, lo que me permite realizar mis tareas con mayor rapidez y precisión. | D6: =RESPUESTAS!E142/1 -> 3 | E6: =((D6*1)/$D$3) -> 0.023076923 | F6: =RESPUESTAS!E143/2 -> 3 | G6: =F6*1/$D$3 -> 0.023076923 | H6: =RESPUESTAS!E144/3 -> 28 | I6: =H6*1/$D$3 -> 0.21538462 | J6: =RESPUESTAS!E145/4 -> 49 | K6: =J6*1/$D$3 -> 0.37692308 | L6: =RESPUESTAS!E146/5 -> 47 | M6: =L6*1/$D$3 -> 0.36153846 | N6: =SUM(D6+F6+H6+J6+L6) -> 130 | O6: =SUM(E6+G6+I6+K6+M6) -> 1
A7: 3 | C7: Conozco las tareas o funciones específicas que debo realizar en DACHASAC. | D7: =RESPUESTAS!F$142/1 -> 0 | E7: =((D7*1)/$D$3) -> 0 | F7: =RESPUESTAS!F$143/2 -> 0 | G7: =F7*1/$D$3 -> 0 | H7: =RESPUESTAS!F$144/3 -> 5 | I7: =H7*1/$D$3 -> 0.038461538 | J7: =RESPUESTAS!F$145/4 -> 26 | K7: =J7*1/$D$3 -> 0.2 | L7: =RESPUESTAS!F$146/5 -> 99 | M7: =L7*1/$D$3 -> 0.76153846 | N7: =SUM(D7+F7+H7+J7+L7) -> 130 | O7: =SUM(E7+G7+I7+K7+M7) -> 1
A8: 4 | B8: COLABORACIÓN | C8: En mi equipo de trabajo, puedo expresar mi punto de vista, aun cuando contradiga al de los demás miembros | D8: =RESPUESTAS!G$142/1 -> 3 | E8: =((D8*1)/$D$3) -> 0.023076923 | F8: =RESPUESTAS!G$143/2 -> 2 | G8: =F8*1/$D$3 -> 0.015384615 | H8: =RESPUESTAS!G$144/3 -> 23 | I8: =H8*1/$D$3 -> 0.17692308 | J8: =RESPUESTAS!G$145/4 -> 44 | K8: =J8*1/$D$3 -> 0.33846154 | L8: =RESPUESTAS!G$146/5 -> 58 | M8: =L8*1/$D$3 -> 0.44615385 | N8: =SUM(D8+F8+H8+J8+L8) -> 130 | O8: =SUM(E8+G8+I8+K8+M8) -> 1
A9: 5 | C9: Cuento con la colaboración de mis compañeros de área y de otras áreas cuando lo necesito | D9: =RESPUESTAS!H$142/1 -> 1 | E9: =((D9*1)/$D$3) -> 0.0076923077 | F9: =RESPUESTAS!H$143/2 -> 3 | G9: =F9*1/$D$3 -> 0.023076923 | H9: =RESPUESTAS!H$144/3 -> 20 | I9: =H9*1/$D$3 -> 0.15384615 | J9: =RESPUESTAS!H$145/4 -> 51 | K9: =J9*1/$D$3 -> 0.39230769 | L9: =RESPUESTAS!H$146/5 -> 55 | M9: =L9*1/$D$3 -> 0.42307692 | N9: =SUM(D9+F9+H9+J9+L9) -> 130 | O9: =SUM(E9+G9+I9+K9+M9) -> 1
A10: 6 | C10: Tienes una relación sólida y una competencia sana dentro de tu equipo. | D10: =RESPUESTAS!I$142/1 -> 3 | E10: =((D10*1)/$D$3) -> 0.023076923 | F10: =RESPUESTAS!I$143/2 -> 1 | G10: =F10*1/$D$3 -> 0.0076923077 | H10: =RESPUESTAS!I$144/3 -> 7 | I10: =H10*1/$D$3 -> 0.053846154 | J10: =RESPUESTAS!I$145/4 -> 50 | K10: =J10*1/$D$3 -> 0.38461538 | L10: =RESPUESTAS!I$146/5 -> 69 | M10: =L10*1/$D$3 -> 0.53076923 | N10: =SUM(D10+F10+H10+J10+L10) -> 130 | O10: =SUM(E10+G10+I10+K10+M10) -> 1
A11: 7 | B11: VALORACIÓN - MOTIVACION | C11: El trabajo que realizo es valorado por mi jefe inmediato y recibo retroalimentación y/o capacitación constante para mejorar mi desempeño. | D11: =RESPUESTAS!J$142/1 -> 5 | E11: =((D11*1)/$D$3) -> 0.038461538 | F11: =RESPUESTAS!J$143/2 -> 10 | G11: =F11*1/$D$3 -> 0.076923077 | H11: =RESPUESTAS!J$144/3 -> 33 | I11: =H11*1/$D$3 -> 0.25384615 | J11: =RESPUESTAS!J$145/4 -> 37 | K11: =J11*1/$D$3 -> 0.28461538 | L11: =RESPUESTAS!J$146/5 -> 45 | M11: =L11*1/$D$3 -> 0.34615385 | N11: =SUM(D11+F11+H11+J11+L11) -> 130 | O11: =SUM(E11+G11+I11+K11+M11) -> 1
A12: 8 | C12: Mi jefe inmediato se preocupa por crear un ambiente laboral agradable, lo que me motiva a mejorar día a día. | D12: =RESPUESTAS!K$142/1 -> 3 | E12: =((D12*1)/$D$3) -> 0.023076923 | F12: =RESPUESTAS!K$143/2 -> 10 | G12: =F12*1/$D$3 -> 0.076923077 | H12: =RESPUESTAS!K$144/3 -> 22 | I12: =H12*1/$D$3 -> 0.16923077 | J12: =RESPUESTAS!K$145/4 -> 43 | K12: =J12*1/$D$3 -> 0.33076923 | L12: =RESPUESTAS!K$146/5 -> 52 | M12: =L12*1/$D$3 -> 0.4 | N12: =SUM(D12+F12+H12+J12+L12) -> 130 | O12: =SUM(E12+G12+I12+K12+M12) -> 1
A13: 9 | C13: Me gusta lo que hago, me siento motivado a mejorar y mi trabajo me permite desarrollar al máximo mis capacidades. | D13: =RESPUESTAS!L$142/1 -> 0 | E13: =((D13*1)/$D$3) -> 0 | F13: =RESPUESTAS!L$143/2 -> 2 | G13: =F13*1/$D$3 -> 0.015384615 | H13: =RESPUESTAS!L$144/3 -> 19 | I13: =H13*1/$D$3 -> 0.14615385 | J13: =RESPUESTAS!L$145/4 -> 42 | K13: =J13*1/$D$3 -> 0.32307692 | L13: =RESPUESTAS!L$146/5 -> 67 | M13: =L13*1/$D$3 -> 0.51538462 | N13: =SUM(D13+F13+H13+J13+L13) -> 130 | O13: =SUM(E13+G13+I13+K13+M13) -> 1
A14: 10 | B14: COMUNICACIÓN | C14: Mi jefe inmediato me mantiene informado sobre cambios importantes del área y me brinda retroalimentación sobre mi desempeño | D14: =RESPUESTAS!M$142/1 -> 4 | E14: =((D14*1)/$D$3) -> 0.030769231 | F14: =RESPUESTAS!M$143/2 -> 13 | G14: =F14*1/$D$3 -> 0.1 | H14: =RESPUESTAS!M$144/3 -> 23 | I14: =H14*1/$D$3 -> 0.17692308 | J14: =RESPUESTAS!M$145/4 -> 34 | K14: =J14*1/$D$3 -> 0.26153846 | L14: =RESPUESTAS!M$146/5 -> 56 | M14: =L14*1/$D$3 -> 0.43076923 | N14: =SUM(D14+F14+H14+J14+L14) -> 130 | O14: =SUM(E14+G14+I14+K14+M14) -> 1
A15: 11 | C15: Mi jefe inmediato escucha mis opiniones y me hace partícipe de las decisiones | D15: =RESPUESTAS!N$142/1 -> 4 | E15: =((D15*1)/$D$3) -> 0.030769231 | F15: =RESPUESTAS!N$143/2 -> 7 | G15: =F15*1/$D$3 -> 0.053846154 | H15: =RESPUESTAS!N$144/3 -> 24 | I15: =H15*1/$D$3 -> 0.18461538 | J15: =RESPUESTAS!N$145/4 -> 38 | K15: =J15*1/$D$3 -> 0.29230769 | L15: =RESPUESTAS!N$146/5 -> 57 | M15: =L15*1/$D$3 -> 0.43846154 | N15: =SUM(D15+F15+H15+J15+L15) -> 130 | O15: =SUM(E15+G15+I15+K15+M15) -> 1
A16: 12 | C16: En DACHASAC existen suficientes canales de comunicación. | D16: =RESPUESTAS!O$142/1 -> 4 | E16: =((D16*1)/$D$3) -> 0.030769231 | F16: =RESPUESTAS!O$143/2 -> 14 | G16: =F16*1/$D$3 -> 0.10769231 | H16: =RESPUESTAS!O$144/3 -> 31 | I16: =H16*1/$D$3 -> 0.23846154 | J16: =RESPUESTAS!O$145/4 -> 45 | K16: =J16*1/$D$3 -> 0.34615385 | L16: =RESPUESTAS!O$146/5 -> 36 | M16: =L16*1/$D$3 -> 0.27692308 | N16: =SUM(D16+F16+H16+J16+L16) -> 130 | O16: =SUM(E16+G16+I16+K16+M16) -> 1
A17: 13 | C17: Las reuniones de coordinación con los miembros de otras áreas son frecuentes. | D17: =RESPUESTAS!P$142/1 -> 13 | E17: =((D17*1)/$D$3) -> 0.1 | F17: =RESPUESTAS!P$143/2 -> 30 | G17: =F17*1/$D$3 -> 0.23076923 | H17: =RESPUESTAS!P$144/3 -> 33 | I17: =H17*1/$D$3 -> 0.25384615 | J17: =RESPUESTAS!P$145/4 -> 34 | K17: =J17*1/$D$3 -> 0.26153846 | L17: =RESPUESTAS!P$146/5 -> 20 | M17: =L17*1/$D$3 -> 0.15384615 | N17: =SUM(D17+F17+H17+J17+L17) -> 130 | O17: =SUM(E17+G17+I17+K17+M17) -> 1
A18: 14 | B18: FORMACIÓN | C18: Las inducciones realizadas al momento de mi ingreso me ayudan a realizar las labores propias de mi puesto de trabajo | D18: =RESPUESTAS!Q$142/1 -> 11 | E18: =((D18*1)/$D$3) -> 0.084615385 | F18: =RESPUESTAS!Q$143/2 -> 7 | G18: =F18*1/$D$3 -> 0.053846154 | H18: =RESPUESTAS!Q$144/3 -> 27 | I18: =H18*1/$D$3 -> 0.20769231 | J18: =RESPUESTAS!Q$145/4 -> 35 | K18: =J18*1/$D$3 -> 0.26923077 | L18: =RESPUESTAS!Q$146/5 -> 50 | M18: =L18*1/$D$3 -> 0.38461538 | N18: =SUM(D18+F18+H18+J18+L18) -> 130 | O18: =SUM(E18+G18+I18+K18+M18) -> 1
A19: 15 | C19: DACHASAC me ofrece oportunidades para crecer profesionalmente | D19: =RESPUESTAS!R$142/1 -> 14 | E19: =((D19*1)/$D$3) -> 0.10769231 | F19: =RESPUESTAS!R$143/2 -> 13 | G19: =F19*1/$D$3 -> 0.1 | H19: =RESPUESTAS!R$144/3 -> 34 | I19: =H19*1/$D$3 -> 0.26153846 | J19: =RESPUESTAS!R$145/4 -> 28 | K19: =J19*1/$D$3 -> 0.21538462 | L19: =RESPUESTAS!R$146/5 -> 41 | M19: =L19*1/$D$3 -> 0.31538462 | N19: =SUM(D19+F19+H19+J19+L19) -> 130 | O19: =SUM(E19+G19+I19+K19+M19) -> 1
A20: 16 | C20: DACHASAC me ofrece capacitaciones y/o entrenamientos para desarrollarme profesionalmente | D20: =RESPUESTAS!S$142/1 -> 20 | E20: =((D20*1)/$D$3) -> 0.15384615 | F20: =RESPUESTAS!S$143/2 -> 15 | G20: =F20*1/$D$3 -> 0.11538462 | H20: =RESPUESTAS!S$144/3 -> 26 | I20: =H20*1/$D$3 -> 0.2 | J20: =RESPUESTAS!S$145/4 -> 38 | K20: =J20*1/$D$3 -> 0.29230769 | L20: =RESPUESTAS!S$146/5 -> 31 | M20: =L20*1/$D$3 -> 0.23846154 | N20: =SUM(D20+F20+H20+J20+L20) -> 130 | O20: =SUM(E20+G20+I20+K20+M20) -> 1
A21: 17 | B21: LIDERAZGO | C21: Mi jefe inmediato está disponible cuando lo necesito y brinda apoyo para superar los obstáculos que se presentan. | D21: =RESPUESTAS!T$142/1 -> 3 | E21: =((D21*1)/$D$3) -> 0.023076923 | F21: =RESPUESTAS!T$143/2 -> 7 | G21: =F21*1/$D$3 -> 0.053846154 | H21: =RESPUESTAS!T$144/3 -> 25 | I21: =H21*1/$D$3 -> 0.19230769 | J21: =RESPUESTAS!T$145/4 -> 35 | K21: =J21*1/$D$3 -> 0.26923077 | L21: =RESPUESTAS!T$146/5 -> 60 | M21: =L21*1/$D$3 -> 0.46153846 | N21: =SUM(D21+F21+H21+J21+L21) -> 130 | O21: =SUM(E21+G21+I21+K21+M21) -> 1
A22: 18 | C22: Mi jefe inmediato es claro y específico al definir los objetivos de trabajo y maneja adecuadamente los conflictos. | D22: =RESPUESTAS!U$142/1 -> 3 | E22: =((D22*1)/$D$3) -> 0.023076923 | F22: =RESPUESTAS!U$143/2 -> 4 | G22: =F22*1/$D$3 -> 0.030769231 | H22: =RESPUESTAS!U$144/3 -> 25 | I22: =H22*1/$D$3 -> 0.19230769 | J22: =RESPUESTAS!U$145/4 -> 41 | K22: =J22*1/$D$3 -> 0.31538462 | L22: =RESPUESTAS!U$146/5 -> 57 | M22: =L22*1/$D$3 -> 0.43846154 | N22: =SUM(D22+F22+H22+J22+L22) -> 130 | O22: =SUM(E22+G22+I22+K22+M22) -> 1
A23: 19 | C23: Nuestros gerentes contribuyen a crear condiciones adecuadas para el progreso de DACHASAC | D23: =RESPUESTAS!V$142/1 -> 7 | E23: =((D23*1)/$D$3) -> 0.053846154 | F23: =RESPUESTAS!V$143/2 -> 9 | G23: =F23*1/$D$3 -> 0.069230769 | H23: =RESPUESTAS!V$144/3 -> 34 | I23: =H23*1/$D$3 -> 0.26153846 | J23: =RESPUESTAS!V$145/4 -> 38 | K23: =J23*1/$D$3 -> 0.29230769 | L23: =RESPUESTAS!V$146/5 -> 42 | M23: =L23*1/$D$3 -> 0.32307692 | N23: =SUM(D23+F23+H23+J23+L23) -> 130 | O23: =SUM(E23+G23+I23+K23+M23) -> 1
A24: 20 | B24: SEGURIDAD | C24: Trabajo en un ambiente seguro y me siento satisfecho. | D24: =RESPUESTAS!W$142/1 -> 4 | E24: =((D24*1)/$D$3) -> 0.030769231 | F24: =RESPUESTAS!W$143/2 -> 4 | G24: =F24*1/$D$3 -> 0.030769231 | H24: =RESPUESTAS!W$144/3 -> 21 | I24: =H24*1/$D$3 -> 0.16153846 | J24: =RESPUESTAS!W$145/4 -> 49 | K24: =J24*1/$D$3 -> 0.37692308 | L24: =RESPUESTAS!W$146/5 -> 52 | M24: =L24*1/$D$3 -> 0.4 | N24: =SUM(D24+F24+H24+J24+L24) -> 130 | O24: =SUM(E24+G24+I24+K24+M24) -> 1
A25: 21 | C25: Dispongo de los materiales, equipos de protección personal y recursos necesarios para realizar mi trabajo de forma segura | D25: =RESPUESTAS!X$142/1 -> 1 | E25: =((D25*1)/$D$3) -> 0.0076923077 | F25: =RESPUESTAS!X$143/2 -> 6 | G25: =F25*1/$D$3 -> 0.046153846 | H25: =RESPUESTAS!X$144/3 -> 11 | I25: =H25*1/$D$3 -> 0.084615385 | J25: =RESPUESTAS!X$145/4 -> 57 | K25: =J25*1/$D$3 -> 0.43846154 | L25: =RESPUESTAS!X$146/5 -> 55 | M25: =L25*1/$D$3 -> 0.42307692 | N25: =SUM(D25+F25+H25+J25+L25) -> 130 | O25: =SUM(E25+G25+I25+K25+M25) -> 1
A26: 22 | C26: DACHASAC me proporciona de los equipos, herramientas y materiales a tiempo. | D26: =RESPUESTAS!Y$142/1 -> 2 | E26: =((D26*1)/$D$3) -> 0.015384615 | F26: =RESPUESTAS!Y$143/2 -> 6 | G26: =F26*1/$D$3 -> 0.046153846 | H26: =RESPUESTAS!Y$144/3 -> 9 | I26: =H26*1/$D$3 -> 0.069230769 | J26: =RESPUESTAS!Y$145/4 -> 48 | K26: =J26*1/$D$3 -> 0.36923077 | L26: =RESPUESTAS!Y$146/5 -> 65 | M26: =L26*1/$D$3 -> 0.5 | N26: =SUM(D26+F26+H26+J26+L26) -> 130 | O26: =SUM(E26+G26+I26+K26+M26) -> 1
A27: 23 | B27: REMUNERACIÓN | C27: Recibo mi remuneración a tiempo | D27: =RESPUESTAS!Z$142/1 -> 1 | E27: =((D27*1)/$D$3) -> 0.0076923077 | F27: =RESPUESTAS!Z$143/2 -> 2 | G27: =F27*1/$D$3 -> 0.015384615 | H27: =RESPUESTAS!Z$144/3 -> 28 | I27: =H27*1/$D$3 -> 0.21538462 | J27: =RESPUESTAS!Z$145/4 -> 56 | K27: =J27*1/$D$3 -> 0.43076923 | L27: =RESPUESTAS!Z$146/5 -> 43 | M27: =L27*1/$D$3 -> 0.33076923 | N27: =SUM(D27+F27+H27+J27+L27) -> 130 | O27: =SUM(E27+G27+I27+K27+M27) -> 1
A28: 24 | C28: Existe equidad en las remuneraciones | D28: =RESPUESTAS!AA$142/1 -> 15 | E28: =((D28*1)/$D$3) -> 0.11538462 | F28: =RESPUESTAS!AA$143/2 -> 24 | G28: =F28*1/$D$3 -> 0.18461538 | H28: =RESPUESTAS!AA$144/3 -> 32 | I28: =H28*1/$D$3 -> 0.24615385 | J28: =RESPUESTAS!AA$145/4 -> 33 | K28: =J28*1/$D$3 -> 0.25384615 | L28: =RESPUESTAS!AA$146/5 -> 26 | M28: =L28*1/$D$3 -> 0.2 | N28: =SUM(D28+F28+H28+J28+L28) -> 130 | O28: =SUM(E28+G28+I28+K28+M28) -> 1
A29: 25 | C29: Mi remuneración es adecuada en relación con el trabajo que realizo | D29: =RESPUESTAS!AB$142/1 -> 22 | E29: =((D29*1)/$D$3) -> 0.16923077 | F29: =RESPUESTAS!AB$143/2 -> 26 | G29: =F29*1/$D$3 -> 0.2 | H29: =RESPUESTAS!AB$144/3 -> 32 | I29: =H29*1/$D$3 -> 0.24615385 | J29: =RESPUESTAS!AB$145/4 -> 26 | K29: =J29*1/$D$3 -> 0.2 | L29: =RESPUESTAS!AB$146/5 -> 24 | M29: =L29*1/$D$3 -> 0.18461538 | N29: =SUM(D29+F29+H29+J29+L29) -> 130 | O29: =SUM(E29+G29+I29+K29+M29) -> 1
